[2024-06-13 20:01:45,006] {taskinstance.py:1159} INFO - Dependencies all met for <TaskInstance: s3_to_ml_to_postgres.extract_data_from_s3 manual__2024-06-13T20:01:43.926911+00:00 [queued]>
[2024-06-13 20:01:45,010] {taskinstance.py:1159} INFO - Dependencies all met for <TaskInstance: s3_to_ml_to_postgres.extract_data_from_s3 manual__2024-06-13T20:01:43.926911+00:00 [queued]>
[2024-06-13 20:01:45,010] {taskinstance.py:1356} INFO - 
--------------------------------------------------------------------------------
[2024-06-13 20:01:45,010] {taskinstance.py:1357} INFO - Starting attempt 1 of 2
[2024-06-13 20:01:45,011] {taskinstance.py:1358} INFO - 
--------------------------------------------------------------------------------
[2024-06-13 20:01:45,016] {taskinstance.py:1377} INFO - Executing <Task(PythonOperator): extract_data_from_s3> on 2024-06-13 20:01:43.926911+00:00
[2024-06-13 20:01:45,018] {standard_task_runner.py:52} INFO - Started process 3646 to run task
[2024-06-13 20:01:45,020] {standard_task_runner.py:79} INFO - Running: ['***', 'tasks', 'run', 's3_to_ml_to_postgres', 'extract_data_from_s3', 'manual__2024-06-13T20:01:43.926911+00:00', '--job-id', '5', '--raw', '--subdir', 'DAGS_FOLDER/ml_dataset_preparation.py', '--cfg-path', '/tmp/tmpcf6omi80', '--error-file', '/tmp/tmpu56cdm7v']
[2024-06-13 20:01:45,020] {standard_task_runner.py:80} INFO - Job 5: Subtask extract_data_from_s3
[2024-06-13 20:01:45,042] {task_command.py:370} INFO - Running <TaskInstance: s3_to_ml_to_postgres.extract_data_from_s3 manual__2024-06-13T20:01:43.926911+00:00 [running]> on host 92769061d4a4
[2024-06-13 20:01:45,069] {taskinstance.py:1571} INFO - Exporting the following env vars:
AIRFLOW_CTX_DAG_OWNER=***
AIRFLOW_CTX_DAG_ID=s3_to_ml_to_postgres
AIRFLOW_CTX_TASK_ID=extract_data_from_s3
AIRFLOW_CTX_EXECUTION_DATE=2024-06-13T20:01:43.926911+00:00
AIRFLOW_CTX_TRY_NUMBER=1
AIRFLOW_CTX_DAG_RUN_ID=manual__2024-06-13T20:01:43.926911+00:00
[2024-06-13 20:01:45,070] {taskinstance.py:1889} ERROR - Task failed with exception
Traceback (most recent call last):
  File "/home/airflow/.local/lib/python3.7/site-packages/airflow/operators/python.py", line 171, in execute
    return_value = self.execute_callable()
  File "/home/airflow/.local/lib/python3.7/site-packages/airflow/operators/python.py", line 189, in execute_callable
    return self.python_callable(*self.op_args, **self.op_kwargs)
  File "/opt/airflow/dags/ml_dataset_preparation.py", line 87, in extract_data_from_s3
    os.makedirs(local_dir, exist_ok=True)
  File "/usr/local/lib/python3.7/os.py", line 213, in makedirs
    makedirs(head, exist_ok=exist_ok)
  File "/usr/local/lib/python3.7/os.py", line 213, in makedirs
    makedirs(head, exist_ok=exist_ok)
  File "/usr/local/lib/python3.7/os.py", line 213, in makedirs
    makedirs(head, exist_ok=exist_ok)
  [Previous line repeated 3 more times]
  File "/usr/local/lib/python3.7/os.py", line 223, in makedirs
    mkdir(name, mode)
PermissionError: [Errno 13] Permission denied: '/Users'
[2024-06-13 20:01:45,073] {taskinstance.py:1400} INFO - Marking task as UP_FOR_RETRY. dag_id=s3_to_ml_to_postgres, task_id=extract_data_from_s3, execution_date=20240613T200143, start_date=20240613T200145, end_date=20240613T200145
[2024-06-13 20:01:45,077] {standard_task_runner.py:97} ERROR - Failed to execute job 5 for task extract_data_from_s3 ([Errno 13] Permission denied: '/Users'; 3646)
[2024-06-13 20:01:45,124] {local_task_job.py:156} INFO - Task exited with return code 1
[2024-06-13 20:01:45,137] {local_task_job.py:273} INFO - 0 downstream tasks scheduled from follow-on schedule check
