[2024-06-19T01:21:30.035+0000] {taskinstance.py:1956} INFO - Dependencies all met for dep_context=non-requeueable deps ti=<TaskInstance: s3_to_ml_to_AmazoneRedshiftServerless.extract_data_from_s3 scheduled__2024-06-18T00:00:00+00:00 [queued]>
[2024-06-19T01:21:30.039+0000] {taskinstance.py:1956} INFO - Dependencies all met for dep_context=requeueable deps ti=<TaskInstance: s3_to_ml_to_AmazoneRedshiftServerless.extract_data_from_s3 scheduled__2024-06-18T00:00:00+00:00 [queued]>
[2024-06-19T01:21:30.039+0000] {taskinstance.py:2170} INFO - Starting attempt 2 of 2
[2024-06-19T01:21:30.045+0000] {taskinstance.py:2191} INFO - Executing <Task(PythonOperator): extract_data_from_s3> on 2024-06-18 00:00:00+00:00
[2024-06-19T01:21:30.048+0000] {standard_task_runner.py:60} INFO - Started process 66017 to run task
[2024-06-19T01:21:30.053+0000] {standard_task_runner.py:87} INFO - Running: ['***', 'tasks', 'run', 's3_to_ml_to_AmazoneRedshiftServerless', 'extract_data_from_s3', 'scheduled__2024-06-18T00:00:00+00:00', '--job-id', '213', '--raw', '--subdir', 'DAGS_FOLDER/ml_dataset_preparation.py', '--cfg-path', '/tmp/tmpvqpslsld']
[2024-06-19T01:21:30.056+0000] {standard_task_runner.py:88} INFO - Job 213: Subtask extract_data_from_s3
[2024-06-19T01:21:30.091+0000] {task_command.py:423} INFO - Running <TaskInstance: s3_to_ml_to_AmazoneRedshiftServerless.extract_data_from_s3 scheduled__2024-06-18T00:00:00+00:00 [running]> on host 22dc78ccc862
[2024-06-19T01:21:30.136+0000] {taskinstance.py:2480} INFO - Exporting env vars: AIRFLOW_CTX_DAG_OWNER='***' AIRFLOW_CTX_DAG_ID='s3_to_ml_to_AmazoneRedshiftServerless' AIRFLOW_CTX_TASK_ID='extract_data_from_s3' AIRFLOW_CTX_EXECUTION_DATE='2024-06-18T00:00:00+00:00' AIRFLOW_CTX_TRY_NUMBER='2' AIRFLOW_CTX_DAG_RUN_ID='scheduled__2024-06-18T00:00:00+00:00'
[2024-06-19T01:21:30.143+0000] {base.py:83} INFO - Using connection ID 'aws_default' for task execution.
[2024-06-19T01:21:30.143+0000] {connection_wrapper.py:378} INFO - AWS Connection (conn_id='aws_default', conn_type='aws') credentials retrieved from login and password.
[2024-06-19T01:21:35.588+0000] {taskinstance.py:2698} ERROR - Task failed with exception
Traceback (most recent call last):
  File "/home/airflow/.local/lib/python3.8/site-packages/airflow/models/taskinstance.py", line 433, in _execute_task
    result = execute_callable(context=context, **execute_callable_kwargs)
  File "/home/airflow/.local/lib/python3.8/site-packages/airflow/operators/python.py", line 199, in execute
    return_value = self.execute_callable()
  File "/home/airflow/.local/lib/python3.8/site-packages/airflow/operators/python.py", line 216, in execute_callable
    return self.python_callable(*self.op_args, **self.op_kwargs)
  File "/opt/airflow/dags/ml_dataset_preparation.py", line 47, in extract_data_from_s3
    file.write(s3_hook.read_key(s3_object, s3_bucket).encode())
  File "/home/airflow/.local/lib/python3.8/site-packages/airflow/providers/amazon/aws/hooks/s3.py", line 137, in wrapper
    return func(*bound_args.args, **bound_args.kwargs)
  File "/home/airflow/.local/lib/python3.8/site-packages/airflow/providers/amazon/aws/hooks/s3.py", line 91, in wrapper
    return func(*bound_args.args, **bound_args.kwargs)
  File "/home/airflow/.local/lib/python3.8/site-packages/airflow/providers/amazon/aws/hooks/s3.py", line 957, in read_key
    return obj.get()["Body"].read().decode("utf-8")
  File "/home/airflow/.local/lib/python3.8/site-packages/boto3/resources/factory.py", line 581, in do_action
    response = action(self, *args, **kwargs)
  File "/home/airflow/.local/lib/python3.8/site-packages/boto3/resources/action.py", line 88, in __call__
    response = getattr(parent.meta.client, operation_name)(*args, **params)
  File "/home/airflow/.local/lib/python3.8/site-packages/botocore/client.py", line 553, in _api_call
    return self._make_api_call(operation_name, kwargs)
  File "/home/airflow/.local/lib/python3.8/site-packages/botocore/client.py", line 1009, in _make_api_call
    raise error_class(parsed_response, operation_name)
botocore.exceptions.ClientError: An error occurred (RequestTimeTooSkewed) when calling the GetObject operation: The difference between the request time and the current time is too large.
[2024-06-19T01:21:35.597+0000] {taskinstance.py:1138} INFO - Marking task as FAILED. dag_id=s3_to_ml_to_AmazoneRedshiftServerless, task_id=extract_data_from_s3, execution_date=20240618T000000, start_date=20240619T012130, end_date=20240619T012135
[2024-06-19T01:21:35.609+0000] {standard_task_runner.py:107} ERROR - Failed to execute job 213 for task extract_data_from_s3 (An error occurred (RequestTimeTooSkewed) when calling the GetObject operation: The difference between the request time and the current time is too large.; 66017)
[2024-06-19T01:21:35.673+0000] {local_task_job_runner.py:234} INFO - Task exited with return code 1
[2024-06-19T01:21:35.687+0000] {taskinstance.py:3280} INFO - 0 downstream tasks scheduled from follow-on schedule check
