[2024-06-14T19:13:46.268+0000] {taskinstance.py:1956} INFO - Dependencies all met for dep_context=non-requeueable deps ti=<TaskInstance: s3_to_ml_to_postgres.setup_create_table manual__2024-06-14T19:12:28.985608+00:00 [queued]>
[2024-06-14T19:13:46.271+0000] {taskinstance.py:1956} INFO - Dependencies all met for dep_context=requeueable deps ti=<TaskInstance: s3_to_ml_to_postgres.setup_create_table manual__2024-06-14T19:12:28.985608+00:00 [queued]>
[2024-06-14T19:13:46.271+0000] {taskinstance.py:2170} INFO - Starting attempt 1 of 2
[2024-06-14T19:13:46.276+0000] {taskinstance.py:2191} INFO - Executing <Task(RedshiftDataOperator): setup_create_table> on 2024-06-14 19:12:28.985608+00:00
[2024-06-14T19:13:46.279+0000] {standard_task_runner.py:60} INFO - Started process 272 to run task
[2024-06-14T19:13:46.280+0000] {standard_task_runner.py:87} INFO - Running: ['***', 'tasks', 'run', 's3_to_ml_to_postgres', 'setup_create_table', 'manual__2024-06-14T19:12:28.985608+00:00', '--job-id', '8', '--raw', '--subdir', 'DAGS_FOLDER/ml_dataset_preparation.py', '--cfg-path', '/tmp/tmpc7gqwke3']
[2024-06-14T19:13:46.281+0000] {standard_task_runner.py:88} INFO - Job 8: Subtask setup_create_table
[2024-06-14T19:13:46.304+0000] {task_command.py:423} INFO - Running <TaskInstance: s3_to_ml_to_postgres.setup_create_table manual__2024-06-14T19:12:28.985608+00:00 [running]> on host 22dc78ccc862
[2024-06-14T19:13:46.335+0000] {taskinstance.py:2480} INFO - Exporting env vars: AIRFLOW_CTX_DAG_OWNER='***' AIRFLOW_CTX_DAG_ID='s3_to_ml_to_postgres' AIRFLOW_CTX_TASK_ID='setup_create_table' AIRFLOW_CTX_EXECUTION_DATE='2024-06-14T19:12:28.985608+00:00' AIRFLOW_CTX_TRY_NUMBER='1' AIRFLOW_CTX_DAG_RUN_ID='manual__2024-06-14T19:12:28.985608+00:00'
[2024-06-14T19:13:46.336+0000] {redshift_data.py:122} INFO - Executing statement: 
CREATE TABLE public.yellow2_201601(
vendorid bigint, 
tpep_pickup_datetime timestamp,
tpep_dropoff_datetime timestamp, 
passenger_count double precision, 
trip_distance double precision, 
ratecodeid double precision, 
store_and_fwd_flag varchar(12), 
Pulocationid bigint, 
dolocationid bigint, 
payment_type bigint, 
fare_amount double precision, 
extra double precision, 
mta_tax double precision, 
tip_amount double precision, 
tolls_amount double precision, 
improvement_surcharge double precision, 
total_amount double precision, 
congestion_surcharge double precision, 
airport_fee double precision);
    
[2024-06-14T19:13:46.339+0000] {base.py:83} INFO - Using connection ID 'aws_default' for task execution.
[2024-06-14T19:13:46.339+0000] {connection_wrapper.py:378} INFO - AWS Connection (conn_id='aws_default', conn_type='aws') credentials retrieved from login and password.
[2024-06-14T19:13:47.272+0000] {taskinstance.py:2698} ERROR - Task failed with exception
Traceback (most recent call last):
  File "/home/airflow/.local/lib/python3.8/site-packages/airflow/models/taskinstance.py", line 433, in _execute_task
    result = execute_callable(context=context, **execute_callable_kwargs)
  File "/home/airflow/.local/lib/python3.8/site-packages/airflow/providers/amazon/aws/operators/redshift_data.py", line 124, in execute
    self.statement_id = self.hook.execute_query(
  File "/home/airflow/.local/lib/python3.8/site-packages/airflow/providers/amazon/aws/hooks/redshift_data.py", line 99, in execute_query
    resp = self.conn.execute_statement(**trim_none_values(kwargs))
  File "/home/airflow/.local/lib/python3.8/site-packages/botocore/client.py", line 553, in _api_call
    return self._make_api_call(operation_name, kwargs)
  File "/home/airflow/.local/lib/python3.8/site-packages/botocore/client.py", line 1009, in _make_api_call
    raise error_class(parsed_response, operation_name)
botocore.errorfactory.ValidationException: An error occurred (ValidationException) when calling the ExecuteStatement operation: Redshift endpoint doesn't exist in this region.
[2024-06-14T19:13:47.289+0000] {taskinstance.py:1138} INFO - Marking task as UP_FOR_RETRY. dag_id=s3_to_ml_to_postgres, task_id=setup_create_table, execution_date=20240614T191228, start_date=20240614T191346, end_date=20240614T191347
[2024-06-14T19:13:47.302+0000] {standard_task_runner.py:107} ERROR - Failed to execute job 8 for task setup_create_table (An error occurred (ValidationException) when calling the ExecuteStatement operation: Redshift endpoint doesn't exist in this region.; 272)
[2024-06-14T19:13:47.323+0000] {local_task_job_runner.py:234} INFO - Task exited with return code 1
[2024-06-14T19:13:47.335+0000] {taskinstance.py:3280} INFO - 0 downstream tasks scheduled from follow-on schedule check
