[2024-06-14T19:11:07.525+0000] {taskinstance.py:1956} INFO - Dependencies all met for dep_context=non-requeueable deps ti=<TaskInstance: s3_to_ml_to_postgres.extract_data_from_s3 manual__2024-06-14T19:11:06.631099+00:00 [queued]>
[2024-06-14T19:11:07.528+0000] {taskinstance.py:1956} INFO - Dependencies all met for dep_context=requeueable deps ti=<TaskInstance: s3_to_ml_to_postgres.extract_data_from_s3 manual__2024-06-14T19:11:06.631099+00:00 [queued]>
[2024-06-14T19:11:07.529+0000] {taskinstance.py:2170} INFO - Starting attempt 1 of 2
[2024-06-14T19:11:07.534+0000] {taskinstance.py:2191} INFO - Executing <Task(PythonOperator): extract_data_from_s3> on 2024-06-14 19:11:06.631099+00:00
[2024-06-14T19:11:07.537+0000] {standard_task_runner.py:60} INFO - Started process 147 to run task
[2024-06-14T19:11:07.539+0000] {standard_task_runner.py:87} INFO - Running: ['***', 'tasks', 'run', 's3_to_ml_to_postgres', 'extract_data_from_s3', 'manual__2024-06-14T19:11:06.631099+00:00', '--job-id', '4', '--raw', '--subdir', 'DAGS_FOLDER/ml_dataset_preparation.py', '--cfg-path', '/tmp/tmp92sdpw8v']
[2024-06-14T19:11:07.541+0000] {standard_task_runner.py:88} INFO - Job 4: Subtask extract_data_from_s3
[2024-06-14T19:11:07.563+0000] {task_command.py:423} INFO - Running <TaskInstance: s3_to_ml_to_postgres.extract_data_from_s3 manual__2024-06-14T19:11:06.631099+00:00 [running]> on host 22dc78ccc862
[2024-06-14T19:11:07.593+0000] {taskinstance.py:2480} INFO - Exporting env vars: AIRFLOW_CTX_DAG_OWNER='***' AIRFLOW_CTX_DAG_ID='s3_to_ml_to_postgres' AIRFLOW_CTX_TASK_ID='extract_data_from_s3' AIRFLOW_CTX_EXECUTION_DATE='2024-06-14T19:11:06.631099+00:00' AIRFLOW_CTX_TRY_NUMBER='1' AIRFLOW_CTX_DAG_RUN_ID='manual__2024-06-14T19:11:06.631099+00:00'
[2024-06-14T19:11:07.598+0000] {base_aws.py:581} WARNING - Unable to find AWS Connection ID 'aws_default', switching to empty.
[2024-06-14T19:11:07.598+0000] {base_aws.py:161} INFO - No connection ID provided. Fallback on boto3 credential strategy (region_name=None). See: https://boto3.amazonaws.com/v1/documentation/api/latest/guide/configuration.html
[2024-06-14T19:11:09.755+0000] {taskinstance.py:2698} ERROR - Task failed with exception
Traceback (most recent call last):
  File "/home/airflow/.local/lib/python3.8/site-packages/airflow/models/taskinstance.py", line 433, in _execute_task
    result = execute_callable(context=context, **execute_callable_kwargs)
  File "/home/airflow/.local/lib/python3.8/site-packages/airflow/operators/python.py", line 199, in execute
    return_value = self.execute_callable()
  File "/home/airflow/.local/lib/python3.8/site-packages/airflow/operators/python.py", line 216, in execute_callable
    return self.python_callable(*self.op_args, **self.op_kwargs)
  File "/opt/airflow/dags/ml_dataset_preparation.py", line 41, in extract_data_from_s3
    s3_objects = s3_hook.list_keys(bucket_name=s3_bucket, prefix=s3_prefix)
  File "/home/airflow/.local/lib/python3.8/site-packages/airflow/providers/amazon/aws/hooks/s3.py", line 91, in wrapper
    return func(*bound_args.args, **bound_args.kwargs)
  File "/home/airflow/.local/lib/python3.8/site-packages/airflow/providers/amazon/aws/hooks/s3.py", line 828, in list_keys
    for page in response:
  File "/home/airflow/.local/lib/python3.8/site-packages/botocore/paginate.py", line 269, in __iter__
    response = self._make_request(current_kwargs)
  File "/home/airflow/.local/lib/python3.8/site-packages/botocore/paginate.py", line 357, in _make_request
    return self._method(**current_kwargs)
  File "/home/airflow/.local/lib/python3.8/site-packages/botocore/client.py", line 553, in _api_call
    return self._make_api_call(operation_name, kwargs)
  File "/home/airflow/.local/lib/python3.8/site-packages/botocore/client.py", line 989, in _make_api_call
    http, parsed_response = self._make_request(
  File "/home/airflow/.local/lib/python3.8/site-packages/botocore/client.py", line 1015, in _make_request
    return self._endpoint.make_request(operation_model, request_dict)
  File "/home/airflow/.local/lib/python3.8/site-packages/botocore/endpoint.py", line 119, in make_request
    return self._send_request(request_dict, operation_model)
  File "/home/airflow/.local/lib/python3.8/site-packages/botocore/endpoint.py", line 198, in _send_request
    request = self.create_request(request_dict, operation_model)
  File "/home/airflow/.local/lib/python3.8/site-packages/botocore/endpoint.py", line 134, in create_request
    self._event_emitter.emit(
  File "/home/airflow/.local/lib/python3.8/site-packages/botocore/hooks.py", line 412, in emit
    return self._emitter.emit(aliased_event_name, **kwargs)
  File "/home/airflow/.local/lib/python3.8/site-packages/botocore/hooks.py", line 256, in emit
    return self._emit(event_name, kwargs)
  File "/home/airflow/.local/lib/python3.8/site-packages/botocore/hooks.py", line 239, in _emit
    response = handler(**kwargs)
  File "/home/airflow/.local/lib/python3.8/site-packages/botocore/signers.py", line 105, in handler
    return self.sign(operation_name, request)
  File "/home/airflow/.local/lib/python3.8/site-packages/botocore/signers.py", line 195, in sign
    auth.add_auth(request)
  File "/home/airflow/.local/lib/python3.8/site-packages/botocore/auth.py", line 418, in add_auth
    raise NoCredentialsError()
botocore.exceptions.NoCredentialsError: Unable to locate credentials
[2024-06-14T19:11:09.760+0000] {taskinstance.py:1138} INFO - Marking task as UP_FOR_RETRY. dag_id=s3_to_ml_to_postgres, task_id=extract_data_from_s3, execution_date=20240614T191106, start_date=20240614T191107, end_date=20240614T191109
[2024-06-14T19:11:09.765+0000] {standard_task_runner.py:107} ERROR - Failed to execute job 4 for task extract_data_from_s3 (Unable to locate credentials; 147)
[2024-06-14T19:11:09.797+0000] {local_task_job_runner.py:234} INFO - Task exited with return code 1
[2024-06-14T19:11:09.810+0000] {taskinstance.py:3280} INFO - 0 downstream tasks scheduled from follow-on schedule check
