[2024-06-16T17:11:26.862+0000] {taskinstance.py:1956} INFO - Dependencies all met for dep_context=non-requeueable deps ti=<TaskInstance: s3_to_ml_to_postgres.transfer_s3_to_redshift manual__2024-06-16T17:08:22.405345+00:00 [queued]>
[2024-06-16T17:11:26.865+0000] {taskinstance.py:1956} INFO - Dependencies all met for dep_context=requeueable deps ti=<TaskInstance: s3_to_ml_to_postgres.transfer_s3_to_redshift manual__2024-06-16T17:08:22.405345+00:00 [queued]>
[2024-06-16T17:11:26.866+0000] {taskinstance.py:2170} INFO - Starting attempt 1 of 2
[2024-06-16T17:11:26.870+0000] {taskinstance.py:2191} INFO - Executing <Task(S3ToRedshiftOperator): transfer_s3_to_redshift> on 2024-06-16 17:08:22.405345+00:00
[2024-06-16T17:11:26.873+0000] {standard_task_runner.py:60} INFO - Started process 27690 to run task
[2024-06-16T17:11:26.874+0000] {standard_task_runner.py:87} INFO - Running: ['***', 'tasks', 'run', 's3_to_ml_to_postgres', 'transfer_s3_to_redshift', 'manual__2024-06-16T17:08:22.405345+00:00', '--job-id', '100', '--raw', '--subdir', 'DAGS_FOLDER/ml_dataset_preparation.py', '--cfg-path', '/tmp/tmpfgxqy08k']
[2024-06-16T17:11:26.876+0000] {standard_task_runner.py:88} INFO - Job 100: Subtask transfer_s3_to_redshift
[2024-06-16T17:11:26.893+0000] {task_command.py:423} INFO - Running <TaskInstance: s3_to_ml_to_postgres.transfer_s3_to_redshift manual__2024-06-16T17:08:22.405345+00:00 [running]> on host 22dc78ccc862
[2024-06-16T17:11:26.920+0000] {taskinstance.py:2480} INFO - Exporting env vars: AIRFLOW_CTX_DAG_OWNER='***' AIRFLOW_CTX_DAG_ID='s3_to_ml_to_postgres' AIRFLOW_CTX_TASK_ID='transfer_s3_to_redshift' AIRFLOW_CTX_EXECUTION_DATE='2024-06-16T17:08:22.405345+00:00' AIRFLOW_CTX_TRY_NUMBER='1' AIRFLOW_CTX_DAG_RUN_ID='manual__2024-06-16T17:08:22.405345+00:00'
[2024-06-16T17:11:26.924+0000] {base.py:83} INFO - Using connection ID 'aws_default' for task execution.
[2024-06-16T17:11:26.926+0000] {base.py:83} INFO - Using connection ID 'aws_default' for task execution.
[2024-06-16T17:11:26.926+0000] {connection_wrapper.py:378} INFO - AWS Connection (conn_id='aws_default', conn_type='aws') credentials retrieved from login and password.
[2024-06-16T17:11:26.931+0000] {s3_to_redshift.py:192} INFO - Executing COPY command...
[2024-06-16T17:11:26.933+0000] {base.py:83} INFO - Using connection ID 'redshift_conn_id' for task execution.
[2024-06-16T17:11:27.031+0000] {taskinstance.py:2698} ERROR - Task failed with exception
Traceback (most recent call last):
  File "/home/airflow/.local/lib/python3.8/site-packages/redshift_connector/core.py", line 624, in __init__
    hostport: typing.Tuple[str, int] = Connection.__get_host_address_info(host, port)
  File "/home/airflow/.local/lib/python3.8/site-packages/redshift_connector/core.py", line 404, in __get_host_address_info
    response = socket.getaddrinfo(host=host, port=port, family=socket.AF_INET)
  File "/usr/local/lib/python3.8/socket.py", line 918, in getaddrinfo
    for res in _socket.getaddrinfo(host, port, family, type, proto, flags):
socket.gaierror: [Errno -2] Name or service not known

During handling of the above exception, another exception occurred:

Traceback (most recent call last):
  File "/home/airflow/.local/lib/python3.8/site-packages/airflow/models/taskinstance.py", line 433, in _execute_task
    result = execute_callable(context=context, **execute_callable_kwargs)
  File "/home/airflow/.local/lib/python3.8/site-packages/airflow/providers/amazon/aws/transfers/s3_to_redshift.py", line 196, in execute
    redshift_hook.run(sql, autocommit=self.autocommit)
  File "/home/airflow/.local/lib/python3.8/site-packages/airflow/providers/common/sql/hooks/sql.py", line 391, in run
    with closing(self.get_conn()) as conn:
  File "/home/airflow/.local/lib/python3.8/site-packages/airflow/providers/amazon/aws/hooks/redshift_sql.py", line 200, in get_conn
    return redshift_connector.connect(**conn_kwargs)
  File "/home/airflow/.local/lib/python3.8/site-packages/redshift_connector/__init__.py", line 376, in connect
    return Connection(
  File "/home/airflow/.local/lib/python3.8/site-packages/redshift_connector/core.py", line 689, in __init__
    raise InterfaceError("communication error", e)
redshift_connector.error.InterfaceError: ('communication error', gaierror(-2, 'Name or service not known'))
[2024-06-16T17:11:27.035+0000] {taskinstance.py:1138} INFO - Marking task as UP_FOR_RETRY. dag_id=s3_to_ml_to_postgres, task_id=transfer_s3_to_redshift, execution_date=20240616T170822, start_date=20240616T171126, end_date=20240616T171127
[2024-06-16T17:11:27.040+0000] {standard_task_runner.py:107} ERROR - Failed to execute job 100 for task transfer_s3_to_redshift (('communication error', gaierror(-2, 'Name or service not known')); 27690)
[2024-06-16T17:11:27.071+0000] {local_task_job_runner.py:234} INFO - Task exited with return code 1
[2024-06-16T17:11:27.079+0000] {taskinstance.py:3280} INFO - 0 downstream tasks scheduled from follow-on schedule check
