[2024-06-14 00:12:25,563] {taskinstance.py:1159} INFO - Dependencies all met for <TaskInstance: s3_to_ml_to_postgres.extract_data_from_s3 scheduled__2024-06-13T00:00:00+00:00 [queued]>
[2024-06-14 00:12:25,567] {taskinstance.py:1159} INFO - Dependencies all met for <TaskInstance: s3_to_ml_to_postgres.extract_data_from_s3 scheduled__2024-06-13T00:00:00+00:00 [queued]>
[2024-06-14 00:12:25,567] {taskinstance.py:1356} INFO - 
--------------------------------------------------------------------------------
[2024-06-14 00:12:25,567] {taskinstance.py:1357} INFO - Starting attempt 1 of 2
[2024-06-14 00:12:25,567] {taskinstance.py:1358} INFO - 
--------------------------------------------------------------------------------
[2024-06-14 00:12:25,573] {taskinstance.py:1377} INFO - Executing <Task(PythonOperator): extract_data_from_s3> on 2024-06-13 00:00:00+00:00
[2024-06-14 00:12:25,576] {standard_task_runner.py:52} INFO - Started process 9693 to run task
[2024-06-14 00:12:25,580] {standard_task_runner.py:79} INFO - Running: ['***', 'tasks', 'run', 's3_to_ml_to_postgres', 'extract_data_from_s3', 'scheduled__2024-06-13T00:00:00+00:00', '--job-id', '14', '--raw', '--subdir', 'DAGS_FOLDER/ml_dataset_preparation.py', '--cfg-path', '/tmp/tmpjo7eota6', '--error-file', '/tmp/tmpa23x2cij']
[2024-06-14 00:12:25,581] {standard_task_runner.py:80} INFO - Job 14: Subtask extract_data_from_s3
[2024-06-14 00:12:25,610] {task_command.py:370} INFO - Running <TaskInstance: s3_to_ml_to_postgres.extract_data_from_s3 scheduled__2024-06-13T00:00:00+00:00 [running]> on host 92769061d4a4
[2024-06-14 00:12:25,646] {taskinstance.py:1571} INFO - Exporting the following env vars:
AIRFLOW_CTX_DAG_OWNER=***
AIRFLOW_CTX_DAG_ID=s3_to_ml_to_postgres
AIRFLOW_CTX_TASK_ID=extract_data_from_s3
AIRFLOW_CTX_EXECUTION_DATE=2024-06-13T00:00:00+00:00
AIRFLOW_CTX_TRY_NUMBER=1
AIRFLOW_CTX_DAG_RUN_ID=scheduled__2024-06-13T00:00:00+00:00
[2024-06-14 00:12:25,654] {base.py:68} INFO - Using connection ID 'aws_default' for task execution.
[2024-06-14 00:12:25,654] {base_aws.py:206} INFO - Credentials retrieved from login
[2024-06-14 00:12:26,005] {base.py:68} INFO - Using connection ID 'aws_default' for task execution.
[2024-06-14 00:12:26,006] {base_aws.py:206} INFO - Credentials retrieved from login
[2024-06-14 00:12:26,314] {base.py:68} INFO - Using connection ID 'aws_default' for task execution.
[2024-06-14 00:12:26,314] {base_aws.py:206} INFO - Credentials retrieved from login
[2024-06-14 00:12:26,719] {base.py:68} INFO - Using connection ID 'aws_default' for task execution.
[2024-06-14 00:12:26,719] {base_aws.py:206} INFO - Credentials retrieved from login
[2024-06-14 00:12:27,292] {base.py:68} INFO - Using connection ID 'aws_default' for task execution.
[2024-06-14 00:12:27,293] {base_aws.py:206} INFO - Credentials retrieved from login
[2024-06-14 00:12:27,621] {base.py:68} INFO - Using connection ID 'aws_default' for task execution.
[2024-06-14 00:12:27,622] {base_aws.py:206} INFO - Credentials retrieved from login
[2024-06-14 00:12:28,000] {base.py:68} INFO - Using connection ID 'aws_default' for task execution.
[2024-06-14 00:12:28,001] {base_aws.py:206} INFO - Credentials retrieved from login
[2024-06-14 00:12:28,384] {base.py:68} INFO - Using connection ID 'aws_default' for task execution.
[2024-06-14 00:12:28,385] {base_aws.py:206} INFO - Credentials retrieved from login
[2024-06-14 00:12:28,702] {base.py:68} INFO - Using connection ID 'aws_default' for task execution.
[2024-06-14 00:12:28,702] {base_aws.py:206} INFO - Credentials retrieved from login
[2024-06-14 00:12:29,094] {base.py:68} INFO - Using connection ID 'aws_default' for task execution.
[2024-06-14 00:12:29,095] {base_aws.py:206} INFO - Credentials retrieved from login
[2024-06-14 00:12:30,240] {taskinstance.py:1889} ERROR - Task failed with exception
Traceback (most recent call last):
  File "/home/airflow/.local/lib/python3.7/site-packages/urllib3/response.py", line 441, in _error_catcher
    yield
  File "/home/airflow/.local/lib/python3.7/site-packages/urllib3/response.py", line 518, in read
    data = self._fp.read() if not fp_closed else b""
  File "/usr/local/lib/python3.7/http/client.py", line 478, in read
    s = self._safe_read(self.length)
  File "/usr/local/lib/python3.7/http/client.py", line 630, in _safe_read
    raise IncompleteRead(b''.join(s), amt)
http.client.IncompleteRead: IncompleteRead(18940 bytes read, 21546 more expected)

During handling of the above exception, another exception occurred:

Traceback (most recent call last):
  File "/home/airflow/.local/lib/python3.7/site-packages/botocore/response.py", line 99, in read
    chunk = self._raw_stream.read(amt)
  File "/home/airflow/.local/lib/python3.7/site-packages/urllib3/response.py", line 544, in read
    raise IncompleteRead(self._fp_bytes_read, self.length_remaining)
  File "/usr/local/lib/python3.7/contextlib.py", line 130, in __exit__
    self.gen.throw(type, value, traceback)
  File "/home/airflow/.local/lib/python3.7/site-packages/urllib3/response.py", line 458, in _error_catcher
    raise ProtocolError("Connection broken: %r" % e, e)
urllib3.exceptions.ProtocolError: ('Connection broken: IncompleteRead(18940 bytes read, 21546 more expected)', IncompleteRead(18940 bytes read, 21546 more expected))

During handling of the above exception, another exception occurred:

Traceback (most recent call last):
  File "/home/airflow/.local/lib/python3.7/site-packages/airflow/operators/python.py", line 171, in execute
    return_value = self.execute_callable()
  File "/home/airflow/.local/lib/python3.7/site-packages/airflow/operators/python.py", line 189, in execute_callable
    return self.python_callable(*self.op_args, **self.op_kwargs)
  File "/opt/airflow/dags/ml_dataset_preparation.py", line 101, in extract_data_from_s3
    file.write(s3_hook.read_key(s3_object, s3_bucket).encode())
  File "/home/airflow/.local/lib/python3.7/site-packages/airflow/providers/amazon/aws/hooks/s3.py", line 63, in wrapper
    return func(*bound_args.args, **bound_args.kwargs)
  File "/home/airflow/.local/lib/python3.7/site-packages/airflow/providers/amazon/aws/hooks/s3.py", line 91, in wrapper
    return func(*bound_args.args, **bound_args.kwargs)
  File "/home/airflow/.local/lib/python3.7/site-packages/airflow/providers/amazon/aws/hooks/s3.py", line 481, in read_key
    return obj.get()['Body'].read().decode('utf-8')
  File "/home/airflow/.local/lib/python3.7/site-packages/botocore/response.py", line 104, in read
    raise ResponseStreamingError(error=e)
botocore.exceptions.ResponseStreamingError: An error occurred while reading from response stream: ('Connection broken: IncompleteRead(18940 bytes read, 21546 more expected)', IncompleteRead(18940 bytes read, 21546 more expected))
[2024-06-14 00:12:30,250] {taskinstance.py:1400} INFO - Marking task as UP_FOR_RETRY. dag_id=s3_to_ml_to_postgres, task_id=extract_data_from_s3, execution_date=20240613T000000, start_date=20240614T001225, end_date=20240614T001230
[2024-06-14 00:12:30,263] {standard_task_runner.py:97} ERROR - Failed to execute job 14 for task extract_data_from_s3 (An error occurred while reading from response stream: ('Connection broken: IncompleteRead(18940 bytes read, 21546 more expected)', IncompleteRead(18940 bytes read, 21546 more expected)); 9693)
[2024-06-14 00:12:30,278] {local_task_job.py:156} INFO - Task exited with return code 1
[2024-06-14 00:12:30,299] {local_task_job.py:273} INFO - 0 downstream tasks scheduled from follow-on schedule check
[2024-06-14T19:11:05.185+0000] {taskinstance.py:1956} INFO - Dependencies all met for dep_context=non-requeueable deps ti=<TaskInstance: s3_to_ml_to_postgres.extract_data_from_s3 scheduled__2024-06-13T00:00:00+00:00 [queued]>
[2024-06-14T19:11:05.188+0000] {taskinstance.py:1956} INFO - Dependencies all met for dep_context=requeueable deps ti=<TaskInstance: s3_to_ml_to_postgres.extract_data_from_s3 scheduled__2024-06-13T00:00:00+00:00 [queued]>
[2024-06-14T19:11:05.189+0000] {taskinstance.py:2170} INFO - Starting attempt 1 of 2
[2024-06-14T19:11:05.193+0000] {taskinstance.py:2191} INFO - Executing <Task(PythonOperator): extract_data_from_s3> on 2024-06-13 00:00:00+00:00
[2024-06-14T19:11:05.196+0000] {standard_task_runner.py:60} INFO - Started process 136 to run task
[2024-06-14T19:11:05.198+0000] {standard_task_runner.py:87} INFO - Running: ['***', 'tasks', 'run', 's3_to_ml_to_postgres', 'extract_data_from_s3', 'scheduled__2024-06-13T00:00:00+00:00', '--job-id', '3', '--raw', '--subdir', 'DAGS_FOLDER/ml_dataset_preparation.py', '--cfg-path', '/tmp/tmp0541a4f7']
[2024-06-14T19:11:05.199+0000] {standard_task_runner.py:88} INFO - Job 3: Subtask extract_data_from_s3
[2024-06-14T19:11:05.219+0000] {task_command.py:423} INFO - Running <TaskInstance: s3_to_ml_to_postgres.extract_data_from_s3 scheduled__2024-06-13T00:00:00+00:00 [running]> on host 22dc78ccc862
[2024-06-14T19:11:05.245+0000] {taskinstance.py:2480} INFO - Exporting env vars: AIRFLOW_CTX_DAG_OWNER='***' AIRFLOW_CTX_DAG_ID='s3_to_ml_to_postgres' AIRFLOW_CTX_TASK_ID='extract_data_from_s3' AIRFLOW_CTX_EXECUTION_DATE='2024-06-13T00:00:00+00:00' AIRFLOW_CTX_TRY_NUMBER='1' AIRFLOW_CTX_DAG_RUN_ID='scheduled__2024-06-13T00:00:00+00:00'
[2024-06-14T19:11:05.249+0000] {base_aws.py:581} WARNING - Unable to find AWS Connection ID 'aws_default', switching to empty.
[2024-06-14T19:11:05.249+0000] {base_aws.py:161} INFO - No connection ID provided. Fallback on boto3 credential strategy (region_name=None). See: https://boto3.amazonaws.com/v1/documentation/api/latest/guide/configuration.html
[2024-06-14T19:11:07.427+0000] {taskinstance.py:2698} ERROR - Task failed with exception
Traceback (most recent call last):
  File "/home/airflow/.local/lib/python3.8/site-packages/airflow/models/taskinstance.py", line 433, in _execute_task
    result = execute_callable(context=context, **execute_callable_kwargs)
  File "/home/airflow/.local/lib/python3.8/site-packages/airflow/operators/python.py", line 199, in execute
    return_value = self.execute_callable()
  File "/home/airflow/.local/lib/python3.8/site-packages/airflow/operators/python.py", line 216, in execute_callable
    return self.python_callable(*self.op_args, **self.op_kwargs)
  File "/opt/airflow/dags/ml_dataset_preparation.py", line 41, in extract_data_from_s3
    s3_objects = s3_hook.list_keys(bucket_name=s3_bucket, prefix=s3_prefix)
  File "/home/airflow/.local/lib/python3.8/site-packages/airflow/providers/amazon/aws/hooks/s3.py", line 91, in wrapper
    return func(*bound_args.args, **bound_args.kwargs)
  File "/home/airflow/.local/lib/python3.8/site-packages/airflow/providers/amazon/aws/hooks/s3.py", line 828, in list_keys
    for page in response:
  File "/home/airflow/.local/lib/python3.8/site-packages/botocore/paginate.py", line 269, in __iter__
    response = self._make_request(current_kwargs)
  File "/home/airflow/.local/lib/python3.8/site-packages/botocore/paginate.py", line 357, in _make_request
    return self._method(**current_kwargs)
  File "/home/airflow/.local/lib/python3.8/site-packages/botocore/client.py", line 553, in _api_call
    return self._make_api_call(operation_name, kwargs)
  File "/home/airflow/.local/lib/python3.8/site-packages/botocore/client.py", line 989, in _make_api_call
    http, parsed_response = self._make_request(
  File "/home/airflow/.local/lib/python3.8/site-packages/botocore/client.py", line 1015, in _make_request
    return self._endpoint.make_request(operation_model, request_dict)
  File "/home/airflow/.local/lib/python3.8/site-packages/botocore/endpoint.py", line 119, in make_request
    return self._send_request(request_dict, operation_model)
  File "/home/airflow/.local/lib/python3.8/site-packages/botocore/endpoint.py", line 198, in _send_request
    request = self.create_request(request_dict, operation_model)
  File "/home/airflow/.local/lib/python3.8/site-packages/botocore/endpoint.py", line 134, in create_request
    self._event_emitter.emit(
  File "/home/airflow/.local/lib/python3.8/site-packages/botocore/hooks.py", line 412, in emit
    return self._emitter.emit(aliased_event_name, **kwargs)
  File "/home/airflow/.local/lib/python3.8/site-packages/botocore/hooks.py", line 256, in emit
    return self._emit(event_name, kwargs)
  File "/home/airflow/.local/lib/python3.8/site-packages/botocore/hooks.py", line 239, in _emit
    response = handler(**kwargs)
  File "/home/airflow/.local/lib/python3.8/site-packages/botocore/signers.py", line 105, in handler
    return self.sign(operation_name, request)
  File "/home/airflow/.local/lib/python3.8/site-packages/botocore/signers.py", line 195, in sign
    auth.add_auth(request)
  File "/home/airflow/.local/lib/python3.8/site-packages/botocore/auth.py", line 418, in add_auth
    raise NoCredentialsError()
botocore.exceptions.NoCredentialsError: Unable to locate credentials
[2024-06-14T19:11:07.431+0000] {taskinstance.py:1138} INFO - Marking task as UP_FOR_RETRY. dag_id=s3_to_ml_to_postgres, task_id=extract_data_from_s3, execution_date=20240613T000000, start_date=20240614T191105, end_date=20240614T191107
[2024-06-14T19:11:07.438+0000] {standard_task_runner.py:107} ERROR - Failed to execute job 3 for task extract_data_from_s3 (Unable to locate credentials; 136)
[2024-06-14T19:11:07.475+0000] {local_task_job_runner.py:234} INFO - Task exited with return code 1
[2024-06-14T19:11:07.487+0000] {taskinstance.py:3280} INFO - 0 downstream tasks scheduled from follow-on schedule check
