[2024-06-14 01:27:59,184] {taskinstance.py:1159} INFO - Dependencies all met for <TaskInstance: s3_to_ml_to_postgres.extract_data_from_s3 scheduled__2024-06-13T00:00:00+00:00 [queued]>
[2024-06-14 01:27:59,188] {taskinstance.py:1159} INFO - Dependencies all met for <TaskInstance: s3_to_ml_to_postgres.extract_data_from_s3 scheduled__2024-06-13T00:00:00+00:00 [queued]>
[2024-06-14 01:27:59,188] {taskinstance.py:1356} INFO - 
--------------------------------------------------------------------------------
[2024-06-14 01:27:59,188] {taskinstance.py:1357} INFO - Starting attempt 2 of 2
[2024-06-14 01:27:59,188] {taskinstance.py:1358} INFO - 
--------------------------------------------------------------------------------
[2024-06-14 01:27:59,195] {taskinstance.py:1377} INFO - Executing <Task(PythonOperator): extract_data_from_s3> on 2024-06-13 00:00:00+00:00
[2024-06-14 01:27:59,197] {standard_task_runner.py:52} INFO - Started process 9723 to run task
[2024-06-14 01:27:59,198] {standard_task_runner.py:79} INFO - Running: ['***', 'tasks', 'run', 's3_to_ml_to_postgres', 'extract_data_from_s3', 'scheduled__2024-06-13T00:00:00+00:00', '--job-id', '15', '--raw', '--subdir', 'DAGS_FOLDER/ml_dataset_preparation.py', '--cfg-path', '/tmp/tmpq01jjl3g', '--error-file', '/tmp/tmpo3_q370t']
[2024-06-14 01:27:59,199] {standard_task_runner.py:80} INFO - Job 15: Subtask extract_data_from_s3
[2024-06-14 01:27:59,221] {task_command.py:370} INFO - Running <TaskInstance: s3_to_ml_to_postgres.extract_data_from_s3 scheduled__2024-06-13T00:00:00+00:00 [running]> on host 92769061d4a4
[2024-06-14 01:27:59,248] {taskinstance.py:1571} INFO - Exporting the following env vars:
AIRFLOW_CTX_DAG_OWNER=***
AIRFLOW_CTX_DAG_ID=s3_to_ml_to_postgres
AIRFLOW_CTX_TASK_ID=extract_data_from_s3
AIRFLOW_CTX_EXECUTION_DATE=2024-06-13T00:00:00+00:00
AIRFLOW_CTX_TRY_NUMBER=2
AIRFLOW_CTX_DAG_RUN_ID=scheduled__2024-06-13T00:00:00+00:00
[2024-06-14 01:27:59,253] {base.py:68} INFO - Using connection ID 'aws_default' for task execution.
[2024-06-14 01:27:59,253] {base_aws.py:206} INFO - Credentials retrieved from login
[2024-06-14 01:28:08,058] {taskinstance.py:1889} ERROR - Task failed with exception
Traceback (most recent call last):
  File "/home/airflow/.local/lib/python3.7/site-packages/urllib3/connection.py", line 175, in _new_conn
    (self._dns_host, self.port), self.timeout, **extra_kw
  File "/home/airflow/.local/lib/python3.7/site-packages/urllib3/util/connection.py", line 72, in create_connection
    for res in socket.getaddrinfo(host, port, family, socket.SOCK_STREAM):
  File "/usr/local/lib/python3.7/socket.py", line 752, in getaddrinfo
    for res in _socket.getaddrinfo(host, port, family, type, proto, flags):
socket.gaierror: [Errno -2] Name or service not known

During handling of the above exception, another exception occurred:

Traceback (most recent call last):
  File "/home/airflow/.local/lib/python3.7/site-packages/botocore/httpsession.py", line 452, in send
    chunked=self._chunked(request.headers),
  File "/home/airflow/.local/lib/python3.7/site-packages/urllib3/connectionpool.py", line 786, in urlopen
    method, url, error=e, _pool=self, _stacktrace=sys.exc_info()[2]
  File "/home/airflow/.local/lib/python3.7/site-packages/urllib3/util/retry.py", line 525, in increment
    raise six.reraise(type(error), error, _stacktrace)
  File "/home/airflow/.local/lib/python3.7/site-packages/urllib3/packages/six.py", line 770, in reraise
    raise value
  File "/home/airflow/.local/lib/python3.7/site-packages/urllib3/connectionpool.py", line 710, in urlopen
    chunked=chunked,
  File "/home/airflow/.local/lib/python3.7/site-packages/urllib3/connectionpool.py", line 386, in _make_request
    self._validate_conn(conn)
  File "/home/airflow/.local/lib/python3.7/site-packages/urllib3/connectionpool.py", line 1040, in _validate_conn
    conn.connect()
  File "/home/airflow/.local/lib/python3.7/site-packages/urllib3/connection.py", line 358, in connect
    self.sock = conn = self._new_conn()
  File "/home/airflow/.local/lib/python3.7/site-packages/urllib3/connection.py", line 187, in _new_conn
    self, "Failed to establish a new connection: %s" % e
urllib3.exceptions.NewConnectionError: <botocore.awsrequest.AWSHTTPSConnection object at 0xffff87ffaad0>: Failed to establish a new connection: [Errno -2] Name or service not known

During handling of the above exception, another exception occurred:

Traceback (most recent call last):
  File "/home/airflow/.local/lib/python3.7/site-packages/airflow/operators/python.py", line 171, in execute
    return_value = self.execute_callable()
  File "/home/airflow/.local/lib/python3.7/site-packages/airflow/operators/python.py", line 189, in execute_callable
    return self.python_callable(*self.op_args, **self.op_kwargs)
  File "/opt/airflow/dags/ml_dataset_preparation.py", line 95, in extract_data_from_s3
    s3_objects = s3_hook.list_keys(bucket_name=s3_bucket, prefix=s3_prefix)
  File "/home/airflow/.local/lib/python3.7/site-packages/airflow/providers/amazon/aws/hooks/s3.py", line 63, in wrapper
    return func(*bound_args.args, **bound_args.kwargs)
  File "/home/airflow/.local/lib/python3.7/site-packages/airflow/providers/amazon/aws/hooks/s3.py", line 370, in list_keys
    for page in response:
  File "/home/airflow/.local/lib/python3.7/site-packages/botocore/paginate.py", line 264, in __iter__
    response = self._make_request(current_kwargs)
  File "/home/airflow/.local/lib/python3.7/site-packages/botocore/paginate.py", line 352, in _make_request
    return self._method(**current_kwargs)
  File "/home/airflow/.local/lib/python3.7/site-packages/botocore/client.py", line 508, in _api_call
    return self._make_api_call(operation_name, kwargs)
  File "/home/airflow/.local/lib/python3.7/site-packages/botocore/client.py", line 895, in _make_api_call
    operation_model, request_dict, request_context
  File "/home/airflow/.local/lib/python3.7/site-packages/botocore/client.py", line 917, in _make_request
    return self._endpoint.make_request(operation_model, request_dict)
  File "/home/airflow/.local/lib/python3.7/site-packages/botocore/endpoint.py", line 116, in make_request
    return self._send_request(request_dict, operation_model)
  File "/home/airflow/.local/lib/python3.7/site-packages/botocore/endpoint.py", line 204, in _send_request
    exception,
  File "/home/airflow/.local/lib/python3.7/site-packages/botocore/endpoint.py", line 358, in _needs_retry
    request_dict=request_dict,
  File "/home/airflow/.local/lib/python3.7/site-packages/botocore/hooks.py", line 412, in emit
    return self._emitter.emit(aliased_event_name, **kwargs)
  File "/home/airflow/.local/lib/python3.7/site-packages/botocore/hooks.py", line 256, in emit
    return self._emit(event_name, kwargs)
  File "/home/airflow/.local/lib/python3.7/site-packages/botocore/hooks.py", line 239, in _emit
    response = handler(**kwargs)
  File "/home/airflow/.local/lib/python3.7/site-packages/botocore/retryhandler.py", line 207, in __call__
    if self._checker(**checker_kwargs):
  File "/home/airflow/.local/lib/python3.7/site-packages/botocore/retryhandler.py", line 285, in __call__
    attempt_number, response, caught_exception
  File "/home/airflow/.local/lib/python3.7/site-packages/botocore/retryhandler.py", line 320, in _should_retry
    return self._checker(attempt_number, response, caught_exception)
  File "/home/airflow/.local/lib/python3.7/site-packages/botocore/retryhandler.py", line 364, in __call__
    attempt_number, response, caught_exception
  File "/home/airflow/.local/lib/python3.7/site-packages/botocore/retryhandler.py", line 248, in __call__
    attempt_number, caught_exception
  File "/home/airflow/.local/lib/python3.7/site-packages/botocore/retryhandler.py", line 416, in _check_caught_exception
    raise caught_exception
  File "/home/airflow/.local/lib/python3.7/site-packages/botocore/endpoint.py", line 278, in _do_get_response
    http_response = self._send(request)
  File "/home/airflow/.local/lib/python3.7/site-packages/botocore/endpoint.py", line 374, in _send
    return self.http_session.send(request)
  File "/home/airflow/.local/lib/python3.7/site-packages/botocore/httpsession.py", line 472, in send
    raise EndpointConnectionError(endpoint_url=request.url, error=e)
botocore.exceptions.EndpointConnectionError: Could not connect to the endpoint URL: "https://velib-project.s3.amazonaws.com/?list-type=2&prefix=realtime_data_velib%2F&delimiter=&start-after=&encoding-type=url"
[2024-06-14 01:28:08,063] {taskinstance.py:1400} INFO - Marking task as FAILED. dag_id=s3_to_ml_to_postgres, task_id=extract_data_from_s3, execution_date=20240613T000000, start_date=20240614T012759, end_date=20240614T012808
[2024-06-14 01:28:08,067] {standard_task_runner.py:97} ERROR - Failed to execute job 15 for task extract_data_from_s3 (Could not connect to the endpoint URL: "https://velib-project.s3.amazonaws.com/?list-type=2&prefix=realtime_data_velib%2F&delimiter=&start-after=&encoding-type=url"; 9723)
[2024-06-14 01:28:08,326] {local_task_job.py:156} INFO - Task exited with return code 1
[2024-06-14 01:28:08,374] {local_task_job.py:273} INFO - 0 downstream tasks scheduled from follow-on schedule check
[2024-06-14T19:16:08.644+0000] {taskinstance.py:1956} INFO - Dependencies all met for dep_context=non-requeueable deps ti=<TaskInstance: s3_to_ml_to_postgres.extract_data_from_s3 scheduled__2024-06-13T00:00:00+00:00 [queued]>
[2024-06-14T19:16:08.647+0000] {taskinstance.py:1956} INFO - Dependencies all met for dep_context=requeueable deps ti=<TaskInstance: s3_to_ml_to_postgres.extract_data_from_s3 scheduled__2024-06-13T00:00:00+00:00 [queued]>
[2024-06-14T19:16:08.647+0000] {taskinstance.py:2170} INFO - Starting attempt 2 of 2
[2024-06-14T19:16:08.652+0000] {taskinstance.py:2191} INFO - Executing <Task(PythonOperator): extract_data_from_s3> on 2024-06-13 00:00:00+00:00
[2024-06-14T19:16:08.655+0000] {standard_task_runner.py:60} INFO - Started process 371 to run task
[2024-06-14T19:16:08.656+0000] {standard_task_runner.py:87} INFO - Running: ['***', 'tasks', 'run', 's3_to_ml_to_postgres', 'extract_data_from_s3', 'scheduled__2024-06-13T00:00:00+00:00', '--job-id', '9', '--raw', '--subdir', 'DAGS_FOLDER/ml_dataset_preparation.py', '--cfg-path', '/tmp/tmpxwf_mccr']
[2024-06-14T19:16:08.658+0000] {standard_task_runner.py:88} INFO - Job 9: Subtask extract_data_from_s3
[2024-06-14T19:16:08.676+0000] {task_command.py:423} INFO - Running <TaskInstance: s3_to_ml_to_postgres.extract_data_from_s3 scheduled__2024-06-13T00:00:00+00:00 [running]> on host 22dc78ccc862
[2024-06-14T19:16:08.702+0000] {taskinstance.py:2480} INFO - Exporting env vars: AIRFLOW_CTX_DAG_OWNER='***' AIRFLOW_CTX_DAG_ID='s3_to_ml_to_postgres' AIRFLOW_CTX_TASK_ID='extract_data_from_s3' AIRFLOW_CTX_EXECUTION_DATE='2024-06-13T00:00:00+00:00' AIRFLOW_CTX_TRY_NUMBER='2' AIRFLOW_CTX_DAG_RUN_ID='scheduled__2024-06-13T00:00:00+00:00'
[2024-06-14T19:16:08.705+0000] {base.py:83} INFO - Using connection ID 'aws_default' for task execution.
[2024-06-14T19:16:08.706+0000] {connection_wrapper.py:378} INFO - AWS Connection (conn_id='aws_default', conn_type='aws') credentials retrieved from login and password.
[2024-06-14T19:17:24.940+0000] {logging_mixin.py:188} INFO - Downloaded 157 file(s) from S3 to /opt/***/data/extracted_s3_data
[2024-06-14T19:17:24.945+0000] {python.py:201} INFO - Done. Returned value was: None
[2024-06-14T19:17:24.962+0000] {taskinstance.py:1138} INFO - Marking task as SUCCESS. dag_id=s3_to_ml_to_postgres, task_id=extract_data_from_s3, execution_date=20240613T000000, start_date=20240614T191608, end_date=20240614T191724
[2024-06-14T19:17:24.992+0000] {local_task_job_runner.py:234} INFO - Task exited with return code 0
[2024-06-14T19:17:25.007+0000] {taskinstance.py:3280} INFO - 1 downstream tasks scheduled from follow-on schedule check
