[2024-06-17T01:20:36.429+0000] {taskinstance.py:1956} INFO - Dependencies all met for dep_context=non-requeueable deps ti=<TaskInstance: s3_to_ml_to_AmazoneRedshiftServerless.extract_data_from_s3 scheduled__2024-06-16T00:00:00+00:00 [queued]>
[2024-06-17T01:20:36.432+0000] {taskinstance.py:1956} INFO - Dependencies all met for dep_context=requeueable deps ti=<TaskInstance: s3_to_ml_to_AmazoneRedshiftServerless.extract_data_from_s3 scheduled__2024-06-16T00:00:00+00:00 [queued]>
[2024-06-17T01:20:36.433+0000] {taskinstance.py:2170} INFO - Starting attempt 2 of 2
[2024-06-17T01:20:36.437+0000] {taskinstance.py:2191} INFO - Executing <Task(PythonOperator): extract_data_from_s3> on 2024-06-16 00:00:00+00:00
[2024-06-17T01:20:36.440+0000] {standard_task_runner.py:60} INFO - Started process 36566 to run task
[2024-06-17T01:20:36.442+0000] {standard_task_runner.py:87} INFO - Running: ['***', 'tasks', 'run', 's3_to_ml_to_AmazoneRedshiftServerless', 'extract_data_from_s3', 'scheduled__2024-06-16T00:00:00+00:00', '--job-id', '199', '--raw', '--subdir', 'DAGS_FOLDER/ml_dataset_preparation.py', '--cfg-path', '/tmp/tmpss5ksl3v']
[2024-06-17T01:20:36.444+0000] {standard_task_runner.py:88} INFO - Job 199: Subtask extract_data_from_s3
[2024-06-17T01:20:36.466+0000] {task_command.py:423} INFO - Running <TaskInstance: s3_to_ml_to_AmazoneRedshiftServerless.extract_data_from_s3 scheduled__2024-06-16T00:00:00+00:00 [running]> on host 22dc78ccc862
[2024-06-17T01:20:36.496+0000] {taskinstance.py:2480} INFO - Exporting env vars: AIRFLOW_CTX_DAG_OWNER='***' AIRFLOW_CTX_DAG_ID='s3_to_ml_to_AmazoneRedshiftServerless' AIRFLOW_CTX_TASK_ID='extract_data_from_s3' AIRFLOW_CTX_EXECUTION_DATE='2024-06-16T00:00:00+00:00' AIRFLOW_CTX_TRY_NUMBER='2' AIRFLOW_CTX_DAG_RUN_ID='scheduled__2024-06-16T00:00:00+00:00'
[2024-06-17T01:20:36.500+0000] {base.py:83} INFO - Using connection ID 'aws_default' for task execution.
[2024-06-17T01:20:36.500+0000] {connection_wrapper.py:378} INFO - AWS Connection (conn_id='aws_default', conn_type='aws') credentials retrieved from login and password.
[2024-06-17T01:20:51.238+0000] {taskinstance.py:2698} ERROR - Task failed with exception
Traceback (most recent call last):
  File "/home/airflow/.local/lib/python3.8/site-packages/airflow/models/taskinstance.py", line 433, in _execute_task
    result = execute_callable(context=context, **execute_callable_kwargs)
  File "/home/airflow/.local/lib/python3.8/site-packages/airflow/operators/python.py", line 199, in execute
    return_value = self.execute_callable()
  File "/home/airflow/.local/lib/python3.8/site-packages/airflow/operators/python.py", line 216, in execute_callable
    return self.python_callable(*self.op_args, **self.op_kwargs)
  File "/opt/airflow/dags/ml_dataset_preparation.py", line 48, in extract_data_from_s3
    file.write(s3_hook.read_key(s3_object, s3_bucket).encode())
  File "/home/airflow/.local/lib/python3.8/site-packages/airflow/providers/amazon/aws/hooks/s3.py", line 137, in wrapper
    return func(*bound_args.args, **bound_args.kwargs)
  File "/home/airflow/.local/lib/python3.8/site-packages/airflow/providers/amazon/aws/hooks/s3.py", line 91, in wrapper
    return func(*bound_args.args, **bound_args.kwargs)
  File "/home/airflow/.local/lib/python3.8/site-packages/airflow/providers/amazon/aws/hooks/s3.py", line 956, in read_key
    obj = self.get_key(key, bucket_name)
  File "/home/airflow/.local/lib/python3.8/site-packages/airflow/providers/amazon/aws/hooks/s3.py", line 137, in wrapper
    return func(*bound_args.args, **bound_args.kwargs)
  File "/home/airflow/.local/lib/python3.8/site-packages/airflow/providers/amazon/aws/hooks/s3.py", line 91, in wrapper
    return func(*bound_args.args, **bound_args.kwargs)
  File "/home/airflow/.local/lib/python3.8/site-packages/airflow/providers/amazon/aws/hooks/s3.py", line 940, in get_key
    obj.load(**sanitize_extra_args())
  File "/home/airflow/.local/lib/python3.8/site-packages/boto3/resources/factory.py", line 565, in do_action
    response = action(self, *args, **kwargs)
  File "/home/airflow/.local/lib/python3.8/site-packages/boto3/resources/action.py", line 88, in __call__
    response = getattr(parent.meta.client, operation_name)(*args, **params)
  File "/home/airflow/.local/lib/python3.8/site-packages/botocore/client.py", line 553, in _api_call
    return self._make_api_call(operation_name, kwargs)
  File "/home/airflow/.local/lib/python3.8/site-packages/botocore/client.py", line 1009, in _make_api_call
    raise error_class(parsed_response, operation_name)
botocore.exceptions.ClientError: An error occurred (403) when calling the HeadObject operation: Forbidden
[2024-06-17T01:20:51.246+0000] {taskinstance.py:1138} INFO - Marking task as FAILED. dag_id=s3_to_ml_to_AmazoneRedshiftServerless, task_id=extract_data_from_s3, execution_date=20240616T000000, start_date=20240617T012036, end_date=20240617T012051
[2024-06-17T01:20:51.251+0000] {standard_task_runner.py:107} ERROR - Failed to execute job 199 for task extract_data_from_s3 (An error occurred (403) when calling the HeadObject operation: Forbidden; 36566)
[2024-06-17T01:20:51.283+0000] {local_task_job_runner.py:234} INFO - Task exited with return code 1
[2024-06-17T01:20:51.300+0000] {taskinstance.py:3280} INFO - 0 downstream tasks scheduled from follow-on schedule check
