[2024-06-16T17:33:04.252+0000] {taskinstance.py:1956} INFO - Dependencies all met for dep_context=non-requeueable deps ti=<TaskInstance: s3_to_ml_to_postgres.transfer_s3_to_redshift manual__2024-06-16T17:24:37.155373+00:00 [queued]>
[2024-06-16T17:33:04.256+0000] {taskinstance.py:1956} INFO - Dependencies all met for dep_context=requeueable deps ti=<TaskInstance: s3_to_ml_to_postgres.transfer_s3_to_redshift manual__2024-06-16T17:24:37.155373+00:00 [queued]>
[2024-06-16T17:33:04.256+0000] {taskinstance.py:2170} INFO - Starting attempt 2 of 2
[2024-06-16T17:33:04.261+0000] {taskinstance.py:2191} INFO - Executing <Task(S3ToRedshiftOperator): transfer_s3_to_redshift> on 2024-06-16 17:24:37.155373+00:00
[2024-06-16T17:33:04.263+0000] {standard_task_runner.py:60} INFO - Started process 28655 to run task
[2024-06-16T17:33:04.265+0000] {standard_task_runner.py:87} INFO - Running: ['***', 'tasks', 'run', 's3_to_ml_to_postgres', 'transfer_s3_to_redshift', 'manual__2024-06-16T17:24:37.155373+00:00', '--job-id', '114', '--raw', '--subdir', 'DAGS_FOLDER/ml_dataset_preparation.py', '--cfg-path', '/tmp/tmpro2lwk69']
[2024-06-16T17:33:04.266+0000] {standard_task_runner.py:88} INFO - Job 114: Subtask transfer_s3_to_redshift
[2024-06-16T17:33:04.283+0000] {task_command.py:423} INFO - Running <TaskInstance: s3_to_ml_to_postgres.transfer_s3_to_redshift manual__2024-06-16T17:24:37.155373+00:00 [running]> on host 22dc78ccc862
[2024-06-16T17:33:04.312+0000] {taskinstance.py:2480} INFO - Exporting env vars: AIRFLOW_CTX_DAG_OWNER='***' AIRFLOW_CTX_DAG_ID='s3_to_ml_to_postgres' AIRFLOW_CTX_TASK_ID='transfer_s3_to_redshift' AIRFLOW_CTX_EXECUTION_DATE='2024-06-16T17:24:37.155373+00:00' AIRFLOW_CTX_TRY_NUMBER='2' AIRFLOW_CTX_DAG_RUN_ID='manual__2024-06-16T17:24:37.155373+00:00'
[2024-06-16T17:33:04.315+0000] {base.py:83} INFO - Using connection ID 'aws_default' for task execution.
[2024-06-16T17:33:04.317+0000] {base.py:83} INFO - Using connection ID 'aws_default' for task execution.
[2024-06-16T17:33:04.318+0000] {connection_wrapper.py:378} INFO - AWS Connection (conn_id='aws_default', conn_type='aws') credentials retrieved from login and password.
[2024-06-16T17:33:04.322+0000] {s3_to_redshift.py:192} INFO - Executing COPY command...
[2024-06-16T17:33:04.325+0000] {base.py:83} INFO - Using connection ID 'redshift_conn_id' for task execution.
[2024-06-16T17:34:23.257+0000] {taskinstance.py:2698} ERROR - Task failed with exception
Traceback (most recent call last):
  File "/home/airflow/.local/lib/python3.8/site-packages/redshift_connector/core.py", line 626, in __init__
    self._usock.connect(hostport)
ConnectionRefusedError: [Errno 111] Connection refused

During handling of the above exception, another exception occurred:

Traceback (most recent call last):
  File "/home/airflow/.local/lib/python3.8/site-packages/airflow/models/taskinstance.py", line 433, in _execute_task
    result = execute_callable(context=context, **execute_callable_kwargs)
  File "/home/airflow/.local/lib/python3.8/site-packages/airflow/providers/amazon/aws/transfers/s3_to_redshift.py", line 196, in execute
    redshift_hook.run(sql, autocommit=self.autocommit)
  File "/home/airflow/.local/lib/python3.8/site-packages/airflow/providers/common/sql/hooks/sql.py", line 391, in run
    with closing(self.get_conn()) as conn:
  File "/home/airflow/.local/lib/python3.8/site-packages/airflow/providers/amazon/aws/hooks/redshift_sql.py", line 200, in get_conn
    return redshift_connector.connect(**conn_kwargs)
  File "/home/airflow/.local/lib/python3.8/site-packages/redshift_connector/__init__.py", line 376, in connect
    return Connection(
  File "/home/airflow/.local/lib/python3.8/site-packages/redshift_connector/core.py", line 689, in __init__
    raise InterfaceError("communication error", e)
redshift_connector.error.InterfaceError: ('communication error', ConnectionRefusedError(111, 'Connection refused'))
[2024-06-16T17:34:23.275+0000] {taskinstance.py:1138} INFO - Marking task as FAILED. dag_id=s3_to_ml_to_postgres, task_id=transfer_s3_to_redshift, execution_date=20240616T172437, start_date=20240616T173304, end_date=20240616T173423
[2024-06-16T17:34:23.291+0000] {standard_task_runner.py:107} ERROR - Failed to execute job 114 for task transfer_s3_to_redshift (('communication error', ConnectionRefusedError(111, 'Connection refused')); 28655)
[2024-06-16T17:34:23.332+0000] {local_task_job_runner.py:234} INFO - Task exited with return code 1
[2024-06-16T17:34:23.347+0000] {taskinstance.py:3280} INFO - 0 downstream tasks scheduled from follow-on schedule check
