[2024-06-13 20:24:45,575] {taskinstance.py:1159} INFO - Dependencies all met for <TaskInstance: s3_to_ml_to_postgres.transform_data manual__2024-06-13T20:24:36.172682+00:00 [queued]>
[2024-06-13 20:24:45,579] {taskinstance.py:1159} INFO - Dependencies all met for <TaskInstance: s3_to_ml_to_postgres.transform_data manual__2024-06-13T20:24:36.172682+00:00 [queued]>
[2024-06-13 20:24:45,579] {taskinstance.py:1356} INFO - 
--------------------------------------------------------------------------------
[2024-06-13 20:24:45,579] {taskinstance.py:1357} INFO - Starting attempt 1 of 2
[2024-06-13 20:24:45,579] {taskinstance.py:1358} INFO - 
--------------------------------------------------------------------------------
[2024-06-13 20:24:45,585] {taskinstance.py:1377} INFO - Executing <Task(PythonOperator): transform_data> on 2024-06-13 20:24:36.172682+00:00
[2024-06-13 20:24:45,587] {standard_task_runner.py:52} INFO - Started process 4789 to run task
[2024-06-13 20:24:45,589] {standard_task_runner.py:79} INFO - Running: ['***', 'tasks', 'run', 's3_to_ml_to_postgres', 'transform_data', 'manual__2024-06-13T20:24:36.172682+00:00', '--job-id', '10', '--raw', '--subdir', 'DAGS_FOLDER/ml_dataset_preparation.py', '--cfg-path', '/tmp/tmppkr1o05c', '--error-file', '/tmp/tmpiwqn6ap5']
[2024-06-13 20:24:45,589] {standard_task_runner.py:80} INFO - Job 10: Subtask transform_data
[2024-06-13 20:24:45,609] {task_command.py:370} INFO - Running <TaskInstance: s3_to_ml_to_postgres.transform_data manual__2024-06-13T20:24:36.172682+00:00 [running]> on host 92769061d4a4
[2024-06-13 20:24:45,636] {taskinstance.py:1571} INFO - Exporting the following env vars:
AIRFLOW_CTX_DAG_OWNER=***
AIRFLOW_CTX_DAG_ID=s3_to_ml_to_postgres
AIRFLOW_CTX_TASK_ID=transform_data
AIRFLOW_CTX_EXECUTION_DATE=2024-06-13T20:24:36.172682+00:00
AIRFLOW_CTX_TRY_NUMBER=1
AIRFLOW_CTX_DAG_RUN_ID=manual__2024-06-13T20:24:36.172682+00:00
[2024-06-13 20:24:45,636] {taskinstance.py:1889} ERROR - Task failed with exception
Traceback (most recent call last):
  File "/home/airflow/.local/lib/python3.7/site-packages/airflow/operators/python.py", line 171, in execute
    return_value = self.execute_callable()
  File "/home/airflow/.local/lib/python3.7/site-packages/airflow/operators/python.py", line 189, in execute_callable
    return self.python_callable(*self.op_args, **self.op_kwargs)
  File "/opt/airflow/dags/ml_dataset_preparation.py", line 111, in transform_data
    if not os.path.exist(transformed_data_dir):
AttributeError: module 'posixpath' has no attribute 'exist'
[2024-06-13 20:24:45,639] {taskinstance.py:1400} INFO - Marking task as UP_FOR_RETRY. dag_id=s3_to_ml_to_postgres, task_id=transform_data, execution_date=20240613T202436, start_date=20240613T202445, end_date=20240613T202445
[2024-06-13 20:24:45,643] {standard_task_runner.py:97} ERROR - Failed to execute job 10 for task transform_data (module 'posixpath' has no attribute 'exist'; 4789)
[2024-06-13 20:24:45,647] {local_task_job.py:156} INFO - Task exited with return code 1
[2024-06-13 20:24:45,658] {local_task_job.py:273} INFO - 0 downstream tasks scheduled from follow-on schedule check
