[2024-06-18T00:00:00.916+0000] {taskinstance.py:1956} INFO - Dependencies all met for dep_context=non-requeueable deps ti=<TaskInstance: s3_to_ml_to_AmazoneRedshiftServerless.extract_data_from_s3 scheduled__2024-06-17T00:00:00+00:00 [queued]>
[2024-06-18T00:00:00.919+0000] {taskinstance.py:1956} INFO - Dependencies all met for dep_context=requeueable deps ti=<TaskInstance: s3_to_ml_to_AmazoneRedshiftServerless.extract_data_from_s3 scheduled__2024-06-17T00:00:00+00:00 [queued]>
[2024-06-18T00:00:00.920+0000] {taskinstance.py:2170} INFO - Starting attempt 1 of 2
[2024-06-18T00:00:00.924+0000] {taskinstance.py:2191} INFO - Executing <Task(PythonOperator): extract_data_from_s3> on 2024-06-17 00:00:00+00:00
[2024-06-18T00:00:00.926+0000] {standard_task_runner.py:60} INFO - Started process 45131 to run task
[2024-06-18T00:00:00.928+0000] {standard_task_runner.py:87} INFO - Running: ['***', 'tasks', 'run', 's3_to_ml_to_AmazoneRedshiftServerless', 'extract_data_from_s3', 'scheduled__2024-06-17T00:00:00+00:00', '--job-id', '200', '--raw', '--subdir', 'DAGS_FOLDER/ml_dataset_preparation.py', '--cfg-path', '/tmp/tmpqo3z18_8']
[2024-06-18T00:00:00.930+0000] {standard_task_runner.py:88} INFO - Job 200: Subtask extract_data_from_s3
[2024-06-18T00:00:00.948+0000] {task_command.py:423} INFO - Running <TaskInstance: s3_to_ml_to_AmazoneRedshiftServerless.extract_data_from_s3 scheduled__2024-06-17T00:00:00+00:00 [running]> on host 22dc78ccc862
[2024-06-18T00:00:00.974+0000] {taskinstance.py:2480} INFO - Exporting env vars: AIRFLOW_CTX_DAG_OWNER='***' AIRFLOW_CTX_DAG_ID='s3_to_ml_to_AmazoneRedshiftServerless' AIRFLOW_CTX_TASK_ID='extract_data_from_s3' AIRFLOW_CTX_EXECUTION_DATE='2024-06-17T00:00:00+00:00' AIRFLOW_CTX_TRY_NUMBER='1' AIRFLOW_CTX_DAG_RUN_ID='scheduled__2024-06-17T00:00:00+00:00'
[2024-06-18T00:00:00.977+0000] {base.py:83} INFO - Using connection ID 'aws_default' for task execution.
[2024-06-18T00:00:00.978+0000] {connection_wrapper.py:378} INFO - AWS Connection (conn_id='aws_default', conn_type='aws') credentials retrieved from login and password.
[2024-06-18T00:01:09.546+0000] {taskinstance.py:2698} ERROR - Task failed with exception
Traceback (most recent call last):
  File "/home/airflow/.local/lib/python3.8/site-packages/urllib3/response.py", line 444, in _error_catcher
    yield
  File "/home/airflow/.local/lib/python3.8/site-packages/urllib3/response.py", line 567, in read
    data = self._fp_read(amt) if not fp_closed else b""
  File "/home/airflow/.local/lib/python3.8/site-packages/urllib3/response.py", line 533, in _fp_read
    return self._fp.read(amt) if amt is not None else self._fp.read()
  File "/usr/local/lib/python3.8/http/client.py", line 472, in read
    s = self._safe_read(self.length)
  File "/usr/local/lib/python3.8/http/client.py", line 615, in _safe_read
    raise IncompleteRead(data, amt-len(data))
http.client.IncompleteRead: IncompleteRead(1532 bytes read, 38978 more expected)

During handling of the above exception, another exception occurred:

Traceback (most recent call last):
  File "/home/airflow/.local/lib/python3.8/site-packages/botocore/response.py", line 99, in read
    chunk = self._raw_stream.read(amt)
  File "/home/airflow/.local/lib/python3.8/site-packages/urllib3/response.py", line 593, in read
    raise IncompleteRead(self._fp_bytes_read, self.length_remaining)
  File "/usr/local/lib/python3.8/contextlib.py", line 131, in __exit__
    self.gen.throw(type, value, traceback)
  File "/home/airflow/.local/lib/python3.8/site-packages/urllib3/response.py", line 461, in _error_catcher
    raise ProtocolError("Connection broken: %r" % e, e)
urllib3.exceptions.ProtocolError: ('Connection broken: IncompleteRead(1532 bytes read, 38978 more expected)', IncompleteRead(1532 bytes read, 38978 more expected))

During handling of the above exception, another exception occurred:

Traceback (most recent call last):
  File "/home/airflow/.local/lib/python3.8/site-packages/airflow/models/taskinstance.py", line 433, in _execute_task
    result = execute_callable(context=context, **execute_callable_kwargs)
  File "/home/airflow/.local/lib/python3.8/site-packages/airflow/operators/python.py", line 199, in execute
    return_value = self.execute_callable()
  File "/home/airflow/.local/lib/python3.8/site-packages/airflow/operators/python.py", line 216, in execute_callable
    return self.python_callable(*self.op_args, **self.op_kwargs)
  File "/opt/airflow/dags/ml_dataset_preparation.py", line 48, in extract_data_from_s3
    file.write(s3_hook.read_key(s3_object, s3_bucket).encode())
  File "/home/airflow/.local/lib/python3.8/site-packages/airflow/providers/amazon/aws/hooks/s3.py", line 137, in wrapper
    return func(*bound_args.args, **bound_args.kwargs)
  File "/home/airflow/.local/lib/python3.8/site-packages/airflow/providers/amazon/aws/hooks/s3.py", line 91, in wrapper
    return func(*bound_args.args, **bound_args.kwargs)
  File "/home/airflow/.local/lib/python3.8/site-packages/airflow/providers/amazon/aws/hooks/s3.py", line 957, in read_key
    return obj.get()["Body"].read().decode("utf-8")
  File "/home/airflow/.local/lib/python3.8/site-packages/botocore/response.py", line 104, in read
    raise ResponseStreamingError(error=e)
botocore.exceptions.ResponseStreamingError: An error occurred while reading from response stream: ('Connection broken: IncompleteRead(1532 bytes read, 38978 more expected)', IncompleteRead(1532 bytes read, 38978 more expected))
[2024-06-18T00:01:09.563+0000] {taskinstance.py:1138} INFO - Marking task as UP_FOR_RETRY. dag_id=s3_to_ml_to_AmazoneRedshiftServerless, task_id=extract_data_from_s3, execution_date=20240617T000000, start_date=20240618T000000, end_date=20240618T000109
[2024-06-18T00:01:09.572+0000] {standard_task_runner.py:107} ERROR - Failed to execute job 200 for task extract_data_from_s3 (An error occurred while reading from response stream: ('Connection broken: IncompleteRead(1532 bytes read, 38978 more expected)', IncompleteRead(1532 bytes read, 38978 more expected)); 45131)
[2024-06-18T00:01:09.584+0000] {local_task_job_runner.py:234} INFO - Task exited with return code 1
[2024-06-18T00:01:09.597+0000] {taskinstance.py:3280} INFO - 0 downstream tasks scheduled from follow-on schedule check
