[2024-06-15T01:11:25.165+0000] {taskinstance.py:1956} INFO - Dependencies all met for dep_context=non-requeueable deps ti=<TaskInstance: s3_to_ml_to_postgres.extract_data_from_s3 scheduled__2024-06-14T00:00:00+00:00 [queued]>
[2024-06-15T01:11:25.169+0000] {taskinstance.py:1956} INFO - Dependencies all met for dep_context=requeueable deps ti=<TaskInstance: s3_to_ml_to_postgres.extract_data_from_s3 scheduled__2024-06-14T00:00:00+00:00 [queued]>
[2024-06-15T01:11:25.170+0000] {taskinstance.py:2170} INFO - Starting attempt 1 of 2
[2024-06-15T01:11:25.175+0000] {taskinstance.py:2191} INFO - Executing <Task(PythonOperator): extract_data_from_s3> on 2024-06-14 00:00:00+00:00
[2024-06-15T01:11:25.178+0000] {standard_task_runner.py:60} INFO - Started process 5339 to run task
[2024-06-15T01:11:25.183+0000] {standard_task_runner.py:87} INFO - Running: ['***', 'tasks', 'run', 's3_to_ml_to_postgres', 'extract_data_from_s3', 'scheduled__2024-06-14T00:00:00+00:00', '--job-id', '50', '--raw', '--subdir', 'DAGS_FOLDER/ml_dataset_preparation.py', '--cfg-path', '/tmp/tmp2lk4fw7c']
[2024-06-15T01:11:25.187+0000] {standard_task_runner.py:88} INFO - Job 50: Subtask extract_data_from_s3
[2024-06-15T01:11:25.212+0000] {task_command.py:423} INFO - Running <TaskInstance: s3_to_ml_to_postgres.extract_data_from_s3 scheduled__2024-06-14T00:00:00+00:00 [running]> on host 22dc78ccc862
[2024-06-15T01:11:25.248+0000] {taskinstance.py:2480} INFO - Exporting env vars: AIRFLOW_CTX_DAG_OWNER='***' AIRFLOW_CTX_DAG_ID='s3_to_ml_to_postgres' AIRFLOW_CTX_TASK_ID='extract_data_from_s3' AIRFLOW_CTX_EXECUTION_DATE='2024-06-14T00:00:00+00:00' AIRFLOW_CTX_TRY_NUMBER='1' AIRFLOW_CTX_DAG_RUN_ID='scheduled__2024-06-14T00:00:00+00:00'
[2024-06-15T01:11:25.254+0000] {base.py:83} INFO - Using connection ID 'aws_default' for task execution.
[2024-06-15T01:11:25.254+0000] {connection_wrapper.py:378} INFO - AWS Connection (conn_id='aws_default', conn_type='aws') credentials retrieved from login and password.
[2024-06-15T01:11:27.416+0000] {taskinstance.py:2698} ERROR - Task failed with exception
Traceback (most recent call last):
  File "/home/airflow/.local/lib/python3.8/site-packages/airflow/models/taskinstance.py", line 433, in _execute_task
    result = execute_callable(context=context, **execute_callable_kwargs)
  File "/home/airflow/.local/lib/python3.8/site-packages/airflow/operators/python.py", line 199, in execute
    return_value = self.execute_callable()
  File "/home/airflow/.local/lib/python3.8/site-packages/airflow/operators/python.py", line 216, in execute_callable
    return self.python_callable(*self.op_args, **self.op_kwargs)
  File "/opt/airflow/dags/ml_dataset_preparation.py", line 223, in extract_data_from_s3
    s3_objects = s3_hook.list_keys(bucket_name=s3_bucket, prefix=s3_prefix)
  File "/home/airflow/.local/lib/python3.8/site-packages/airflow/providers/amazon/aws/hooks/s3.py", line 91, in wrapper
    return func(*bound_args.args, **bound_args.kwargs)
  File "/home/airflow/.local/lib/python3.8/site-packages/airflow/providers/amazon/aws/hooks/s3.py", line 828, in list_keys
    for page in response:
  File "/home/airflow/.local/lib/python3.8/site-packages/botocore/paginate.py", line 269, in __iter__
    response = self._make_request(current_kwargs)
  File "/home/airflow/.local/lib/python3.8/site-packages/botocore/paginate.py", line 357, in _make_request
    return self._method(**current_kwargs)
  File "/home/airflow/.local/lib/python3.8/site-packages/botocore/client.py", line 553, in _api_call
    return self._make_api_call(operation_name, kwargs)
  File "/home/airflow/.local/lib/python3.8/site-packages/botocore/client.py", line 1009, in _make_api_call
    raise error_class(parsed_response, operation_name)
botocore.exceptions.ClientError: An error occurred (RequestTimeTooSkewed) when calling the ListObjectsV2 operation: The difference between the request time and the current time is too large.
[2024-06-15T01:11:27.429+0000] {taskinstance.py:1138} INFO - Marking task as UP_FOR_RETRY. dag_id=s3_to_ml_to_postgres, task_id=extract_data_from_s3, execution_date=20240614T000000, start_date=20240615T011125, end_date=20240615T011127
[2024-06-15T01:11:27.440+0000] {standard_task_runner.py:107} ERROR - Failed to execute job 50 for task extract_data_from_s3 (An error occurred (RequestTimeTooSkewed) when calling the ListObjectsV2 operation: The difference between the request time and the current time is too large.; 5339)
[2024-06-15T01:11:27.477+0000] {local_task_job_runner.py:234} INFO - Task exited with return code 1
[2024-06-15T01:11:27.495+0000] {taskinstance.py:3280} INFO - 0 downstream tasks scheduled from follow-on schedule check
